Workbook

Sheet 학반 시간표
B1: 학반 | C1: 월 | J1: 화 | Q1: 수 | X1: 목 | AE1: 금 | AL1: 학반 | AM1: 담임
C2: 1 | D2: 2 | E2: 3 | F2: 4 | G2: 5 | H2: 6 | I2: 7 | J2: 1 | K2: 2 | L2: 3 | M2: 4 | N2: 5 | O2: 6 | P2: 7 | Q2: 1 | R2: 2 | S2: 3 | T2: 4 | U2: 5 | V2: 6 | W2: 7 | X2: 1 | Y2: 2 | Z2: 3 | AA2: 4 | AB2: 5 | AC2: 6 | AD2: 7 | AE2: 1 | AF2: 2 | AG2: 3 | AH2: 4 | AI2: 5 | AJ2: 6 | AK2: 7
A3: 1011 | B3: 1-1 | C3: 자율활동 | D3: 체육1 | E3: 공강 | F3: 통합과학1 | G3: 통합사회1 | H3: 공통영어1 | I3: 공통국어1 | J3: 공통국어1 | K3: 한국사1 | L3: 음악 | M3: 공통영어1 | N3: 공통수학1 | O3: 통합사회1 | P3: 통합과학1 | Q3: 한국사1 | R3: 통합과학1 | S3: 진로활동 | T3: 공통영어1 | U3: 공통수학1 | V3: 정보와디지털문해력 | W3: 공강 | X3: 공통수학1 | Y3: 한국사1 | Z3: 공통국어1 | AA3: 통합사회1 | AB3: 체육1 | AC3: 통합과학1 | AD3: 음악 | AE3: 공통수학1 | AF3: 과학탐구실험1 | AG3: 통합사회1 | AH3: 공통영어1 | AI3: 공통국어1 | AJ3: 정보와디지털문해력 | AK3: 동아리 | AL3: 1-1 | AM3: 김윤식
A4: 1012 | C4: 김윤식 | D4: 김한복 | E4: 정민준 | F4: 김수연(생) | G4: 김태윤 | H4: 배서영 | I4: 김지현 | J4: 김지현 | K4: 김윤식 | L4: 박시욱 | M4: 배서영 | N4: 정중흠 | O4: 김대일 | P4: 최병곤 | Q4: 김윤식 | R4: 김서율 | S4: 최영일 | T4: 배서영 | U4: 정중흠 | V4: 정희경 | X4: 정중흠 | Y4: 김윤식 | Z4: 김지현 | AA4: 정성민 | AB4: 김한복 | AC4: 정민준 | AD4: 박시욱 | AE4: 정중흠 | AF4: 윤석준 | AG4: 김태윤 | AH4: 배서영 | AI4: 김지현 | AJ4: 정희경
A5: =A3+10 -> 1021 | B5: 1-2 | C5: 자율활동 | D5: 공통국어1 | E5: 공통수학1 | F5: 음악 | G5: 한국사1 | H5: 통합과학1 | I5: 통합사회1 | J5: 공통영어1 | K5: 공강 | L5: 공통국어1 | M5: 통합사회1 | N5: 통합과학1 | O5: 정보와디지털문해력 | P5: 한국사1 | Q5: 공통영어1 | R5: 공통국어1 | S5: 공통수학1 | T5: 통합과학1 | U5: 한국사1 | V5: 체육1 | W5: 공강 | X5: 통합과학1 | Y5: 음악 | Z5: 과학탐구실험1 | AA5: 통합사회1 | AB5: 공통영어1 | AC5: 공통수학1 | AD5: 공통국어1 | AE5: 정보와디지털문해력 | AF5: 진로활동 | AG5: 공통영어1 | AH5: 공통수학1 | AI5: 체육1 | AJ5: 통합사회1 | AK5: 동아리 | AL5: 1-2 | AM5: 김수연(생)
A6: =A4+10 -> 1022 | C6: 김수연(생) | D6: 김지현 | E6: 정중흠 | F6: 박시욱 | G6: 김윤식 | H6: 정민준 | I6: 김태윤 | J6: 배서영 | K6: 김성민 | L6: 김지현 | M6: 김태윤 | N6: 김서율 | O6: 정희경 | P6: 김윤식 | Q6: 배서영 | R6: 김지현 | S6: 정중흠 | T6: 최병곤 | U6: 김윤식 | V6: 김한복 | X6: 김수연(생) | Y6: 박시욱 | Z6: 윤석준 | AA6: 김대일 | AB6: 배서영 | AC6: 정중흠 | AD6: 김지현 | AE6: 정희경 | AF6: 최영일 | AG6: 배서영 | AH6: 정중흠 | AI6: 김한복 | AJ6: 정성민
A7: =A5+10 -> 1031 | B7: 1-3 | C7: 자율활동 | D7: 공통영어1 | E7: 통합사회1 | F7: 공통국어1 | G7: 체육1 | H7: 통합과학1 | I7: 공통수학1 | J7: 정보와디지털문해력 | K7: 진로활동 | L7: 통합과학1 | M7: 음악 | N7: 한국사1 | O7: 공통영어1 | P7: 공통수학1 | Q7: 통합과학1 | R7: 공통수학1 | S7: 체육1 | T7: 정보와디지털문해력 | U7: 공통국어1 | V7: 통합사회1 | W7: 공강 | X7: 과학탐구실험1 | Y7: 통합과학1 | Z7: 통합사회1 | AA7: 공통국어1 | AB7: 공통수학1 | AC7: 공통영어1 | AD7: 한국사1 | AE7: 한국사1 | AF7: 공통국어1 | AG7: 음악 | AH7: 통합사회1 | AI7: 공강 | AJ7: 공통영어1 | AK7: 동아리 | AL7: 1-3 | AM7: 최병곤
A8: =A6+10 -> 1032 | C8: 최병곤 | D8: 배서영 | E8: 김태윤 | F8: 김지현 | G8: 김한복 | H8: 김서율 | I8: 정중흠 | J8: 정희경 | K8: 최영일 | L8: 김수연(생) | M8: 박시욱 | N8: 김윤식 | O8: 배서영 | P8: 정중흠 | Q8: 정민준 | R8: 정중흠 | S8: 김한복 | T8: 정희경 | U8: 김지현 | V8: 김대일 | X8: 윤석준 | Y8: 최병곤 | Z8: 김태윤 | AA8: 김지현 | AB8: 정중흠 | AC8: 배서영 | AD8: 김윤식 | AE8: 김윤식 | AF8: 김지현 | AG8: 박시욱 | AH8: 정성민 | AI8: 김재연 | AJ8: 배서영
A9: =A7+10 -> 1041 | B9: 1-4 | C9: 자율활동 | D9: 정보와디지털문해력 | E9: 한국사1 | F9: 공통영어1 | G9: 공통수학1 | H9: 진로활동 | I9: 통합과학1 | J9: 통합과학1 | K9: 공통수학1 | L9: 체육1 | M9: 공강 | N9: 공통국어1 | O9: 통합사회1 | P9: 공통영어1 | Q9: 공통국어1 | R9: 통합과학1 | S9: 통합사회1 | T9: 과학탐구실험1 | U9: 음악 | V9: 공통영어1 | W9: 공강 | X9: 공통국어1 | Y9: 공통영어1 | Z9: 공통수학1 | AA9: 한국사1 | AB9: 정보와디지털문해력 | AC9: 통합과학1 | AD9: 통합사회1 | AE9: 공통국어1 | AF9: 통합사회1 | AG9: 체육1 | AH9: 음악 | AI9: 한국사1 | AJ9: 공통수학1 | AK9: 동아리 | AL9: 1-4 | AM9: 김서율
A10: =A8+10 -> 1042 | C10: 김서율 | D10: 정희경 | E10: 김윤식 | F10: 배서영 | G10: 정중흠 | H10: 최영일 | I10: 정민준 | J10: 최병곤 | K10: 정중흠 | L10: 박진우 | M10: 박인영 | N10: 김지현 | O10: 김태윤 | P10: 배서영 | Q10: 김지현 | R10: 김수연(생) | S10: 김태윤 | T10: 윤석준 | U10: 박시욱 | V10: 배서영 | X10: 김지현 | Y10: 배서영 | Z10: 정중흠 | AA10: 김윤식 | AB10: 정희경 | AC10: 김서율 | AD10: 정성민 | AE10: 김지현 | AF10: 김대일 | AG10: 박진우 | AH10: 박시욱 | AI10: 김윤식 | AJ10: 정중흠
A11: =A9+10 -> 1051 | B11: 1-5 | C11: 자율활동 | D11: 통합과학1 | E11: 과학탐구실험1 | F11: 공통국어1 | G11: 공강 | H11: 음악 | I11: 통합사회1 | J11: 공통수학1 | K11: 체육1 | L11: 한국사1 | M11: 정보와디지털문해력 | N11: 공통국어1 | O11: 공통영어1 | P11: 통합사회1 | Q11: 공통영어1 | R11: 음악 | S11: 한국사1 | T11: 통합과학1 | U11: 공통수학1 | V11: 공통국어1 | W11: 공강 | X11: 통합사회1 | Y11: 공통수학1 | Z11: 체육1 | AA11: 통합과학1 | AB11: 공통영어1 | AC11: 정보와디지털문해력 | AD11: 공통국어1 | AE11: 통합과학1 | AF11: 공통수학1 | AG11: 한국사1 | AH11: 통합사회1 | AI11: 진로활동 | AJ11: 공통영어1 | AK11: 동아리 | AL11: 1-5 | AM11: 이철주
A12: =A10+10 -> 1052 | C12: 이철주 | D12: 김서율 | E12: 윤석준 | F12: 김정화 | G12: 신자영 | H12: 박시욱 | I12: 김대일 | J12: 권정훈 | K12: 박진우 | L12: 김윤식 | M12: 정희경 | N12: 김정화 | O12: 이철주 | P12: 정성민 | Q12: 이철주 | R12: 박시욱 | S12: 김윤식 | T12: 김수연(생) | U12: 권정훈 | V12: 김정화 | X12: 김태윤 | Y12: 권정훈 | Z12: 박진우 | AA12: 최병곤 | AB12: 이철주 | AC12: 정희경 | AD12: 김정화 | AE12: 정민준 | AF12: 권정훈 | AG12: 김윤식 | AH12: 김태윤 | AI12: 최영일 | AJ12: 이철주
A13: =A11+10 -> 1061 | B13: 1-6 | C13: 자율활동 | D13: 생활과인성Ⅰ | E13: 음악 | F13: 진로활동 | G13: 체육1 | H13: 공통수학1 | I13: 공통영어1 | J13: 한국사1 | K13: 공통영어1 | L13: 공통국어1 | M13: 통합사회1 | N13: 통합과학1 | O13: 공통수학1 | P13: 과학탐구실험1 | Q13: 공통수학1 | R13: 통합사회1 | S13: 공통국어1 | T13: 체육1 | U13: 생활과인성Ⅰ | V13: 통합과학1 | W13: 공강 | X13: 한국사1 | Y13: 공통국어1 | Z13: 공통영어1 | AA13: 공통수학1 | AB13: 공강 | AC13: 통합사회1 | AD13: 통합과학1 | AE13: 음악 | AF13: 공통국어1 | AG13: 통합과학1 | AH13: 공통영어1 | AI13: 한국사1 | AJ13: 통합사회1 | AK13: 동아리 | AL13: 1-6 | AM13: 정성민
A14: =A12+10 -> 1062 | C14: 정성민 | D14: 장개석 | E14: 박시욱 | F14: 최영일 | G14: 박진우 | H14: 권정훈 | I14: 이철주 | J14: 이인옥 | K14: 이철주 | L14: 김정화 | M14: 정성민 | N14: 최병곤 | O14: 권정훈 | P14: 윤석준 | Q14: 권정훈 | R14: 김태윤 | S14: 김정화 | T14: 박진우 | U14: 장개석 | V14: 정민준 | X14: 이인옥 | Y14: 김정화 | Z14: 이철주 | AA14: 권정훈 | AB14: 윤석준 | AC14: 김태윤 | AD14: 김수연(생) | AE14: 박시욱 | AF14: 김정화 | AG14: 김서율 | AH14: 이철주 | AI14: 이인옥 | AJ14: 김대일
A15: =A13+10 -> 1071 | B15: 1-7 | C15: 자율활동 | D15: 공통수학1 | E15: 공통국어1 | F15: 통합과학1 | G15: 공통영어1 | H15: 통합사회1 | I15: 음악 | J15: 공통국어1 | K15: 공통수학1 | L15: 공통영어1 | M15: 과학탐구실험1 | N15: 생활과인성Ⅰ | O15: 한국사1 | P15: 통합사회1 | Q15: 공강 | R15: 공통영어1 | S15: 음악 | T15: 통합과학1 | U15: 통합사회1 | V15: 체육1 | W15: 공강 | X15: 통합과학1 | Y15: 공통영어1 | Z15: 진로활동 | AA15: 공통국어1 | AB15: 생활과인성Ⅰ | AC15: 한국사1 | AD15: 공통수학1 | AE15: 통합사회1 | AF15: 체육1 | AG15: 한국사1 | AH15: 통합과학1 | AI15: 공통국어1 | AJ15: 공통수학1 | AK15: 동아리 | AL15: 1-7 | AM15: 김정화
A16: =A14+10 -> 1072 | C16: 김정화 | D16: 권정훈 | E16: 김정화 | F16: 최병곤 | G16: 이철주 | H16: 정성민 | I16: 박시욱 | J16: 김정화 | K16: 권정훈 | L16: 이철주 | M16: 전민재 | N16: 장개석 | O16: 이인옥 | P16: 김태윤 | Q16: 박인영 | R16: 이철주 | S16: 박시욱 | T16: 정민준 | U16: 정성민 | V16: 박진우 | X16: 김서율 | Y16: 이철주 | Z16: 최영일 | AA16: 김정화 | AB16: 장개석 | AC16: 이인옥 | AD16: 권정훈 | AE16: 김태윤 | AF16: 박진우 | AG16: 이인옥 | AH16: 김수연(생) | AI16: 김정화 | AJ16: 권정훈
A17: =A15+10 -> 1081 | B17: 1-8 | C17: 자율활동 | D17: 통합사회1 | E17: 공통영어1 | F17: 공통수학1 | G17: 생활과인성Ⅰ | H17: 통합과학1 | I17: 공통국어1 | J17: 음악 | K17: 통합과학1 | L17: 한국사1 | M17: 공강 | N17: 체육1 | O17: 공통국어1 | P17: 공통수학1 | Q17: 한국사1 | R17: 공통국어1 | S17: 공통수학1 | T17: 공통영어1 | U17: 통합사회1 | V17: 진로활동 | W17: 공강 | X17: 생활과인성Ⅰ | Y17: 한국사1 | Z17: 통합사회1 | AA17: 음악 | AB17: 통합과학1 | AC17: 공통영어1 | AD17: 공통국어1 | AE17: 과학탐구실험1 | AF17: 공통영어1 | AG17: 통합사회1 | AH17: 공통수학1 | AI17: 체육1 | AJ17: 통합과학1 | AK17: 동아리 | AL17: 1-8 | AM17: 권정훈
A18: =A16+10 -> 1082 | C18: 권정훈 | D18: 김태윤 | E18: 이철주 | F18: 권정훈 | G18: 장개석 | H18: 김수연(생) | I18: 류호찬 | J18: 박시욱 | K18: 정민준 | L18: 이인옥 | M18: 신자영 | N18: 박진우 | O18: 류호찬 | P18: 권정훈 | Q18: 이인옥 | R18: 류호찬 | S18: 권정훈 | T18: 이철주 | U18: 김태윤 | V18: 최영일 | X18: 장개석 | Y18: 이인옥 | Z18: 정성민 | AA18: 박시욱 | AB18: 김서율 | AC18: 이철주 | AD18: 류호찬 | AE18: 전민재 | AF18: 이철주 | AG18: 정성민 | AH18: 권정훈 | AI18: 박진우 | AJ18: 최병곤
A19: =A17+10 -> 1091 | B19: 1-9 | C19: 자율활동 | D19: 공통국어1 | E19: 통합사회1 | F19: 공강 | G19: 한국사1 | H19: 공통영어1 | I19: 공통수학1 | J19: 통합사회1 | K19: 통합과학1 | L19: 생활과인성Ⅰ | M19: 공통국어1 | N19: 공통수학1 | O19: 공통영어1 | P19: 음악 | Q19: 통합과학1 | R19: 통합사회1 | S19: 체육1 | T19: 공통영어1 | U19: 한국사1 | V19: 과학탐구실험1 | W19: 공강 | X19: 공통수학1 | Y19: 공통국어1 | Z19: 공통영어1 | AA19: 체육1 | AB19: 통합과학1 | AC19: 음악 | AD19: 통합사회1 | AE19: 공통국어1 | AF19: 한국사1 | AG19: 진로활동 | AH19: 통합과학1 | AI19: 생활과인성Ⅰ | AJ19: 공통수학1 | AK19: 동아리 | AL19: 1-9 | AM19: 류호찬
A20: =A18+10 -> 1092 | C20: 류호찬 | D20: 류호찬 | E20: 정성민 | F20: 정희경 | G20: 이인옥 | H20: 박선배 | I20: 배호섭 | J20: 김태윤 | K20: 김서율 | L20: 장개석 | M20: 류호찬 | N20: 배호섭 | O20: 박선배 | P20: 박시욱 | Q20: 김수연(생) | R20: 정성민 | S20: 박진우 | T20: 박선배 | U20: 이인옥 | V20: 전민재 | X20: 배호섭 | Y20: 류호찬 | Z20: 박선배 | AA20: 박진우 | AB20: 정민준 | AC20: 박시욱 | AD20: 김태윤 | AE20: 류호찬 | AF20: 이인옥 | AG20: 최영일 | AH20: 최병곤 | AI20: 장개석 | AJ20: 배호섭
A21: 2011 | B21: 2-1 | C21: 자율활동 | D21: 선택 A | E21: 선택 C | F21: 선택 D | G21: 선택 G | H21: 선택 E | I21: 선택 F | J21: 선택 E | K21: 선택 G | L21: 선택 F | M21: 선택 C | N21: 선택 B | O21: 선택 A | P21: 선택 H | Q21: 선택 B | R21: 선택 C | S21: 선택 D | T21: 선택 A | U21: 선택 H | V21: 선택 G | W21: 공강 | X21: 선택 H | Y21: 선택 B | Z21: 선택 A | AA21: 선택 C | AB21: 선택 D | AC21: 선택 F | AD21: 선택 E | AE21: 선택 B | AF21: 선택 F | AG21: 선택 H | AH21: 선택 G | AI21: 선택 D | AJ21: 선택 E | AK21: 동아리 | AL21: 2-1 | AM21: 하수형
A22: 2012 | C22: 하수형
A23: =A21+10 -> 2021 | B23: 2-2 | C23: 자율활동 | D23: 선택 A | E23: 선택 C | F23: 선택 D | G23: 선택 G | H23: 선택 E | I23: 선택 F | J23: 선택 E | K23: 선택 G | L23: 선택 F | M23: 선택 C | N23: 선택 B | O23: 선택 A | P23: 선택 H | Q23: 선택 B | R23: 선택 C | S23: 선택 D | T23: 선택 A | U23: 선택 H | V23: 선택 G | W23: 공강 | X23: 선택 H | Y23: 선택 B | Z23: 선택 A | AA23: 선택 C | AB23: 선택 D | AC23: 선택 F | AD23: 선택 E | AE23: 선택 B | AF23: 선택 F | AG23: 선택 H | AH23: 선택 G | AI23: 선택 D | AJ23: 선택 E | AK23: 동아리 | AL23: 2-2 | AM23: 권오성
A24: =A22+10 -> 2022 | C24: 권오성
A25: =A23+10 -> 2031 | B25: 2-3 | C25: 자율활동 | D25: 선택 A | E25: 선택 C | F25: 선택 D | G25: 선택 G | H25: 선택 E | I25: 선택 F | J25: 선택 E | K25: 선택 G | L25: 선택 F | M25: 선택 C | N25: 선택 B | O25: 선택 A | P25: 선택 H | Q25: 선택 B | R25: 선택 C | S25: 선택 D | T25: 선택 A | U25: 선택 H | V25: 선택 G | W25: 공강 | X25: 선택 H | Y25: 선택 B | Z25: 선택 A | AA25: 선택 C | AB25: 선택 D | AC25: 선택 F | AD25: 선택 E | AE25: 선택 B | AF25: 선택 F | AG25: 선택 H | AH25: 선택 G | AI25: 선택 D | AJ25: 선택 E | AK25: 동아리 | AL25: 2-3 | AM25: 정진수
A26: =A24+10 -> 2032 | C26: 정진수
A27: =A25+10 -> 2041 | B27: 2-4 | C27: 자율활동 | D27: 선택 A | E27: 선택 C | F27: 선택 D | G27: 선택 G | H27: 선택 E | I27: 선택 F | J27: 선택 E | K27: 선택 G | L27: 선택 F | M27: 선택 C | N27: 선택 B | O27: 선택 A | P27: 선택 H | Q27: 선택 B | R27: 선택 C | S27: 선택 D | T27: 선택 A | U27: 선택 H | V27: 선택 G | W27: 공강 | X27: 선택 H | Y27: 선택 B | Z27: 선택 A | AA27: 선택 C | AB27: 선택 D | AC27: 선택 F | AD27: 선택 E | AE27: 선택 B | AF27: 선택 F | AG27: 선택 H | AH27: 선택 G | AI27: 선택 D | AJ27: 선택 E | AK27: 동아리 | AL27: 2-4 | AM27: 정다현
A28: =A26+10 -> 2042 | C28: 정다현
A29: =A27+10 -> 2051 | B29: 2-5 | C29: 자율활동 | D29: 선택 A | E29: 선택 C | F29: 선택 D | G29: 선택 G | H29: 선택 E | I29: 선택 F | J29: 선택 E | K29: 선택 G | L29: 선택 F | M29: 선택 C | N29: 선택 B | O29: 선택 A | P29: 선택 H | Q29: 선택 B | R29: 선택 C | S29: 선택 D | T29: 선택 A | U29: 선택 H | V29: 선택 G | W29: 공강 | X29: 선택 H | Y29: 선택 B | Z29: 선택 A | AA29: 선택 C | AB29: 선택 D | AC29: 선택 F | AD29: 선택 E | AE29: 선택 B | AF29: 선택 F | AG29: 선택 H | AH29: 선택 G | AI29: 선택 D | AJ29: 선택 E | AK29: 동아리 | AL29: 2-5 | AM29: 김진영
A30: =A28+10 -> 2052 | C30: 김진영
A31: =A29+10 -> 2061 | B31: 2-6 | C31: 자율활동 | D31: 선택 A | E31: 선택 C | F31: 선택 D | G31: 선택 G | H31: 선택 E | I31: 선택 F | J31: 선택 E | K31: 선택 G | L31: 선택 F | M31: 선택 C | N31: 선택 B | O31: 선택 A | P31: 선택 H | Q31: 선택 B | R31: 선택 C | S31: 선택 D | T31: 선택 A | U31: 선택 H | V31: 선택 G | W31: 공강 | X31: 선택 H | Y31: 선택 B | Z31: 선택 A | AA31: 선택 C | AB31: 선택 D | AC31: 선택 F | AD31: 선택 E | AE31: 선택 B | AF31: 선택 F | AG31: 선택 H | AH31: 선택 G | AI31: 선택 D | AJ31: 선택 E | AK31: 동아리 | AL31: 2-6 | AM31: 이진아
A32: =A30+10 -> 2062 | C32: 이진아
A33: =A31+10 -> 2071 | B33: 2-7 | C33: 자율활동 | D33: 선택 A | E33: 선택 C | F33: 선택 D | G33: 선택 G | H33: 선택 E | I33: 선택 F | J33: 선택 E | K33: 선택 G | L33: 선택 F | M33: 선택 C | N33: 선택 B | O33: 선택 A | P33: 선택 H | Q33: 선택 B | R33: 선택 C | S33: 선택 D | T33: 선택 A | U33: 선택 H | V33: 선택 G | W33: 공강 | X33: 선택 H | Y33: 선택 B | Z33: 선택 A | AA33: 선택 C | AB33: 선택 D | AC33: 선택 F | AD33: 선택 E | AE33: 선택 B | AF33: 선택 F | AG33: 선택 H | AH33: 선택 G | AI33: 선택 D | AJ33: 선택 E | AK33: 동아리 | AL33: 2-7 | AM33: 이인옥
A34: =A32+10 -> 2072 | C34: 이인옥
A35: =A33+10 -> 2081 | B35: 2-8 | C35: 자율활동 | D35: 선택 A | E35: 선택 C | F35: 선택 D | G35: 선택 G | H35: 선택 E | I35: 선택 F | J35: 선택 E | K35: 선택 G | L35: 선택 F | M35: 선택 C | N35: 선택 B | O35: 선택 A | P35: 선택 H | Q35: 선택 B | R35: 선택 C | S35: 선택 D | T35: 선택 A | U35: 선택 H | V35: 선택 G | W35: 공강 | X35: 선택 H | Y35: 선택 B | Z35: 선택 A | AA35: 선택 C | AB35: 선택 D | AC35: 선택 F | AD35: 선택 E | AE35: 선택 B | AF35: 선택 F | AG35: 선택 H | AH35: 선택 G | AI35: 선택 D | AJ35: 선택 E | AK35: 동아리 | AL35: 2-8 | AM35: 전민재
A36: =A34+10 -> 2082 | C36: 전민재
A37: =A35+10 -> 2091 | B37: 2-9 | C37: 자율활동 | D37: 선택 A | E37: 선택 C | F37: 선택 D | G37: 선택 G | H37: 선택 E | I37: 선택 F | J37: 선택 E | K37: 선택 G | L37: 선택 F | M37: 선택 C | N37: 선택 B | O37: 선택 A | P37: 선택 H | Q37: 선택 B | R37: 선택 C | S37: 선택 D | T37: 선택 A | U37: 선택 H | V37: 선택 G | W37: 공강 | X37: 선택 H | Y37: 선택 B | Z37: 선택 A | AA37: 선택 C | AB37: 선택 D | AC37: 선택 F | AD37: 선택 E | AE37: 선택 B | AF37: 선택 F | AG37: 선택 H | AH37: 선택 G | AI37: 선택 D | AJ37: 선택 E | AK37: 동아리 | AL37: 2-9 | AM37: 신동호
A38: =A36+10 -> 2092 | C38: 신동호
A39: 3011 | B39: 3-1 | C39: 자율활동 | D39: 선택 F | E39: 선택 A | F39: 선택 G | G39: 선택 D | H39: 선택 E | I39: 진로활동 | J39: 선택 A | K39: 선택 B | L39: 선택 G | M39: 선택 C | N39: 선택 E | O39: 선택 F | P39: 문학개론 | Q39: 선택 A | R39: 선택 C | S39: 선택 G | T39: 선택 D | U39: 선택 B | V39: 체육 탐구 | W39: 공강 | X39: 선택 G | Y39: 선택 C | Z39: 선택 F | AA39: 선택 B | AB39: 선택 D | AC39: 선택 E | AD39: 선택 A | AE39: 공강 | AF39: 선택 B | AG39: 선택 F | AH39: 선택 D | AI39: 선택 E | AJ39: 선택 C | AK39: 동아리 | AL39: 3-1 | AM39: 김성민
A40: 3012 | C40: 김성민 | I40: 김성민 | P40: 하수형 | V40: 박인영 | AE40: 김대일
...

Sheet 출력
A1: 학반 시간표_v2 | H1: 학반 | I1: 2학년 5반 | L1: =IFERROR(VLOOKUP(I1,$O$4:$P$45,2,),"") -> 205
A3: 2026학년도 1학기 임시 | C3: <학반 내 게시> | E3: =I1 -> 2학년 5반 | F3: ="담임 : "&IFERROR(VLOOKUP($L$3,'학반 시간표'!$A$3:$AM$56,V22,),"") -> 담임 : 김진영 | L3: =IFERROR(L1*10+1,"") -> 2051 | M3: =IFERROR(L1*10+2,"") -> 2052
O4: * | P4: *
B5: 월 | C5: 화 | D5: 수 | E5: 목 | F5: 금 | N5: 1 | O5: 1학년 1반 | P5: 101
A6: 1 | B6: =IFERROR(VLOOKUP($L$3,'학반 시간표'!$A$3:$AM$56,R6,),"") -> 자율활동 | C6: =IFERROR(VLOOKUP($L$3,'학반 시간표'!$A$3:$AM$56,S6,),"") -> 선택 E | D6: =IFERROR(VLOOKUP($L$3,'학반 시간표'!$A$3:$AM$56,T6,),"") -> 선택 B | E6: =IFERROR(VLOOKUP($L$3,'학반 시간표'!$A$3:$AM$56,U6,),"") -> 선택 H | F6: =IFERROR(VLOOKUP($L$3,'학반 시간표'!$A$3:$AM$56,V6,),"") -> 선택 B | N6: 2 | O6: 1학년 2반 | P6: =P5+1 -> 102 | R6: 3 | S6: =R18+1 -> 10 | T6: =S18+1 -> 17 | U6: =T18+1 -> 24 | V6: =U18+1 -> 31
B7: =IFERROR(VLOOKUP($M$3,'학반 시간표'!$A$3:$AM$56,R7,),"") -> 김진영 | C7: =IFERROR(VLOOKUP($M$3,'학반 시간표'!$A$3:$AM$56,S7,),"") | D7: =IFERROR(VLOOKUP($M$3,'학반 시간표'!$A$3:$AM$56,T7,),"") | E7: =IFERROR(VLOOKUP($M$3,'학반 시간표'!$A$3:$AM$56,U7,),"") | F7: =IFERROR(VLOOKUP($M$3,'학반 시간표'!$A$3:$AM$56,V7,),"") | N7: 3 | O7: 1학년 3반 | P7: =P6+1 -> 103 | R7: 3 | S7: =R19+1 -> 10 | T7: =S19+1 -> 17 | U7: =T19+1 -> 24 | V7: =U19+1 -> 31
A8: 2 | B8: =IFERROR(VLOOKUP($L$3,'학반 시간표'!$A$3:$AM$56,R8,),"") -> 선택 A | C8: =IFERROR(VLOOKUP($L$3,'학반 시간표'!$A$3:$AM$56,S8,),"") -> 선택 G | D8: =IFERROR(VLOOKUP($L$3,'학반 시간표'!$A$3:$AM$56,T8,),"") -> 선택 C | E8: =IFERROR(VLOOKUP($L$3,'학반 시간표'!$A$3:$AM$56,U8,),"") -> 선택 B | F8: =IFERROR(VLOOKUP($L$3,'학반 시간표'!$A$3:$AM$56,V8,),"") -> 선택 F | N8: 4 | O8: 1학년 4반 | P8: =P7+1 -> 104 | R8: =R6+1 -> 4 | S8: =S6+1 -> 11 | T8: =T6+1 -> 18 | U8: =U6+1 -> 25 | V8: =V6+1 -> 32
B9: =IFERROR(VLOOKUP($M$3,'학반 시간표'!$A$3:$AM$56,R9,),"") | C9: =IFERROR(VLOOKUP($M$3,'학반 시간표'!$A$3:$AM$56,S9,),"") | D9: =IFERROR(VLOOKUP($M$3,'학반 시간표'!$A$3:$AM$56,T9,),"") | E9: =IFERROR(VLOOKUP($M$3,'학반 시간표'!$A$3:$AM$56,U9,),"") | F9: =IFERROR(VLOOKUP($M$3,'학반 시간표'!$A$3:$AM$56,V9,),"") | N9: 5 | O9: 1학년 5반 | P9: =P8+1 -> 105 | R9: =R7+1 -> 4 | S9: =S7+1 -> 11 | T9: =T7+1 -> 18 | U9: =U7+1 -> 25 | V9: =V7+1 -> 32
A10: 3 | B10: =IFERROR(VLOOKUP($L$3,'학반 시간표'!$A$3:$AM$56,R10,),"") -> 선택 C | C10: =IFERROR(VLOOKUP($L$3,'학반 시간표'!$A$3:$AM$56,S10,),"") -> 선택 F | D10: =IFERROR(VLOOKUP($L$3,'학반 시간표'!$A$3:$AM$56,T10,),"") -> 선택 D | E10: =IFERROR(VLOOKUP($L$3,'학반 시간표'!$A$3:$AM$56,U10,),"") -> 선택 A | F10: =IFERROR(VLOOKUP($L$3,'학반 시간표'!$A$3:$AM$56,V10,),"") -> 선택 H | N10: 6 | O10: 1학년 6반 | P10: =P9+1 -> 106 | R10: =R8+1 -> 5 | S10: =S8+1 -> 12 | T10: =T8+1 -> 19 | U10: =U8+1 -> 26 | V10: =V8+1 -> 33
B11: =IFERROR(VLOOKUP($M$3,'학반 시간표'!$A$3:$AM$56,R11,),"") | C11: =IFERROR(VLOOKUP($M$3,'학반 시간표'!$A$3:$AM$56,S11,),"") | D11: =IFERROR(VLOOKUP($M$3,'학반 시간표'!$A$3:$AM$56,T11,),"") | E11: =IFERROR(VLOOKUP($M$3,'학반 시간표'!$A$3:$AM$56,U11,),"") | F11: =IFERROR(VLOOKUP($M$3,'학반 시간표'!$A$3:$AM$56,V11,),"") | N11: 7 | O11: 1학년 7반 | P11: =P10+1 -> 107 | R11: =R9+1 -> 5 | S11: =S9+1 -> 12 | T11: =T9+1 -> 19 | U11: =U9+1 -> 26 | V11: =V9+1 -> 33
A12: 4 | B12: =IFERROR(VLOOKUP($L$3,'학반 시간표'!$A$3:$AM$56,R12,),"") -> 선택 D | C12: =IFERROR(VLOOKUP($L$3,'학반 시간표'!$A$3:$AM$56,S12,),"") -> 선택 C | D12: =IFERROR(VLOOKUP($L$3,'학반 시간표'!$A$3:$AM$56,T12,),"") -> 선택 A | E12: =IFERROR(VLOOKUP($L$3,'학반 시간표'!$A$3:$AM$56,U12,),"") -> 선택 C | F12: =IFERROR(VLOOKUP($L$3,'학반 시간표'!$A$3:$AM$56,V12,),"") -> 선택 G | N12: 8 | O12: 1학년 8반 | P12: =P11+1 -> 108 | R12: =R10+1 -> 6 | S12: =S10+1 -> 13 | T12: =T10+1 -> 20 | U12: =U10+1 -> 27 | V12: =V10+1 -> 34
B13: =IFERROR(VLOOKUP($M$3,'학반 시간표'!$A$3:$AM$56,R13,),"") | C13: =IFERROR(VLOOKUP($M$3,'학반 시간표'!$A$3:$AM$56,S13,),"") | D13: =IFERROR(VLOOKUP($M$3,'학반 시간표'!$A$3:$AM$56,T13,),"") | E13: =IFERROR(VLOOKUP($M$3,'학반 시간표'!$A$3:$AM$56,U13,),"") | F13: =IFERROR(VLOOKUP($M$3,'학반 시간표'!$A$3:$AM$56,V13,),"") | N13: 9 | O13: 1학년 9반 | P13: =P12+1 -> 109 | R13: =R11+1 -> 6 | S13: =S11+1 -> 13 | T13: =T11+1 -> 20 | U13: =U11+1 -> 27 | V13: =V11+1 -> 34
A14: 5 | B14: =IFERROR(VLOOKUP($L$3,'학반 시간표'!$A$3:$AM$56,R14,),"") -> 선택 G | C14: =IFERROR(VLOOKUP($L$3,'학반 시간표'!$A$3:$AM$56,S14,),"") -> 선택 B | D14: =IFERROR(VLOOKUP($L$3,'학반 시간표'!$A$3:$AM$56,T14,),"") -> 선택 H | E14: =IFERROR(VLOOKUP($L$3,'학반 시간표'!$A$3:$AM$56,U14,),"") -> 선택 D | F14: =IFERROR(VLOOKUP($L$3,'학반 시간표'!$A$3:$AM$56,V14,),"") -> 선택 D | N14: 10 | O14: 2학년 1반 | P14: 201 | R14: =R12+1 -> 7 | S14: =S12+1 -> 14 | T14: =T12+1 -> 21 | U14: =U12+1 -> 28 | V14: =V12+1 -> 35
B15: =IFERROR(VLOOKUP($M$3,'학반 시간표'!$A$3:$AM$56,R15,),"") | C15: =IFERROR(VLOOKUP($M$3,'학반 시간표'!$A$3:$AM$56,S15,),"") | D15: =IFERROR(VLOOKUP($M$3,'학반 시간표'!$A$3:$AM$56,T15,),"") | E15: =IFERROR(VLOOKUP($M$3,'학반 시간표'!$A$3:$AM$56,U15,),"") | F15: =IFERROR(VLOOKUP($M$3,'학반 시간표'!$A$3:$AM$56,V15,),"") | N15: 11 | O15: 2학년 2반 | P15: =P14+1 -> 202 | R15: =R13+1 -> 7 | S15: =S13+1 -> 14 | T15: =T13+1 -> 21 | U15: =U13+1 -> 28 | V15: =V13+1 -> 35
A16: 6 | B16: =IFERROR(VLOOKUP($L$3,'학반 시간표'!$A$3:$AM$56,R16,),"") -> 선택 E | C16: =IFERROR(VLOOKUP($L$3,'학반 시간표'!$A$3:$AM$56,S16,),"") -> 선택 A | D16: =IFERROR(VLOOKUP($L$3,'학반 시간표'!$A$3:$AM$56,T16,),"") -> 선택 G | E16: =IFERROR(VLOOKUP($L$3,'학반 시간표'!$A$3:$AM$56,U16,),"") -> 선택 F | F16: =IFERROR(VLOOKUP($L$3,'학반 시간표'!$A$3:$AM$56,V16,),"") -> 선택 E | N16: 12 | O16: 2학년 3반 | P16: =P15+1 -> 203 | R16: =R14+1 -> 8 | S16: =S14+1 -> 15 | T16: =T14+1 -> 22 | U16: =U14+1 -> 29 | V16: =V14+1 -> 36
B17: =IFERROR(VLOOKUP($M$3,'학반 시간표'!$A$3:$AM$56,R17,),"") | C17: =IFERROR(VLOOKUP($M$3,'학반 시간표'!$A$3:$AM$56,S17,),"") | D17: =IFERROR(VLOOKUP($M$3,'학반 시간표'!$A$3:$AM$56,T17,),"") | E17: =IFERROR(VLOOKUP($M$3,'학반 시간표'!$A$3:$AM$56,U17,),"") | F17: =IFERROR(VLOOKUP($M$3,'학반 시간표'!$A$3:$AM$56,V17,),"") | N17: 13 | O17: 2학년 4반 | P17: =P16+1 -> 204 | R17: =R15+1 -> 8 | S17: =S15+1 -> 15 | T17: =T15+1 -> 22 | U17: =U15+1 -> 29 | V17: =V15+1 -> 36
A18: 7 | B18: =IFERROR(VLOOKUP($L$3,'학반 시간표'!$A$3:$AM$56,R18,),"") -> 선택 F | C18: =IFERROR(VLOOKUP($L$3,'학반 시간표'!$A$3:$AM$56,S18,),"") -> 선택 H | D18: =IFERROR(VLOOKUP($L$3,'학반 시간표'!$A$3:$AM$56,T18,),"") -> 공강 | E18: =IFERROR(VLOOKUP($L$3,'학반 시간표'!$A$3:$AM$56,U18,),"") -> 선택 E | F18: =IFERROR(VLOOKUP($L$3,'학반 시간표'!$A$3:$AM$56,V18,),"") -> 동아리 | N18: 14 | O18: 2학년 5반 | P18: =P17+1 -> 205 | R18: =R16+1 -> 9 | S18: =S16+1 -> 16 | T18: =T16+1 -> 23 | U18: =U16+1 -> 30 | V18: =V16+1 -> 37
B19: =IFERROR(VLOOKUP($M$3,'학반 시간표'!$A$3:$AM$56,R19,),"") | C19: =IFERROR(VLOOKUP($M$3,'학반 시간표'!$A$3:$AM$56,S19,),"") | D19: =IFERROR(VLOOKUP($M$3,'학반 시간표'!$A$3:$AM$56,T19,),"") | E19: =IFERROR(VLOOKUP($M$3,'학반 시간표'!$A$3:$AM$56,U19,),"") | F19: =IFERROR(VLOOKUP($M$3,'학반 시간표'!$A$3:$AM$56,V19,),"") | N19: 15 | O19: 2학년 6반 | P19: =P18+1 -> 206 | R19: =R17+1 -> 9 | S19: =S17+1 -> 16 | T19: =T17+1 -> 23 | U19: =U17+1 -> 30 | V19: =V17+1 -> 37
N20: 16 | O20: 2학년 7반 | P20: =P19+1 -> 207
N21: 17 | O21: 2학년 8반 | P21: =P20+1 -> 208
N22: 18 | O22: 2학년 9반 | P22: =P21+1 -> 209 | V22: 39
N23: 19 | O23: 3학년 1반 | P23: 301
N24: 20 | O24: 3학년 2반 | P24: =P23+1 -> 302
N25: 21 | O25: 3학년 3반 | P25: =P24+1 -> 303
N26: =N25+1 -> 22 | O26: 3학년 4반 | P26: =P25+1 -> 304
N27: =N26+1 -> 23 | O27: 3학년 5반 | P27: =P26+1 -> 305
N28: =N27+1 -> 24 | O28: 3학년 6반 | P28: =P27+1 -> 306
N29: =N28+1 -> 25 | O29: 3학년 7반 | P29: =P28+1 -> 307
N30: =N29+1 -> 26 | O30: 3학년 8반 | P30: =P29+1 -> 308
N31: =N30+1 -> 27 | O31: 3학년 9반 | P31: =P30+1 -> 309

Sheet 선택과목 묶음
B2: 2학년 선택 | C2: 1반 | D2: 2반 | E2: 3반 | F2: 4반 | G2: 5반 | H2: 6반 | I2: 7반 | J2: 8반 | K2: 9반
B3: A | C3: 생명과학 | D3: 미적분Ⅰ | E3: 생활과 인성Ⅰ | F3: 예술진체 | G3: 대수 | H3: 현대사회와 윤리 | I3: 영어Ⅰ | J3: 화학 | K3: 대수
B4: B | C4: 물리학 | D4: 질문 기반 주제 탐구 | E4: 예술진체 | F4: 미적분Ⅰ | G4: 문학 | H4: 사회와 문화 | I4: 문학 | J4: 인공지능 교과 탐구 | K4: 영어Ⅰ
B5: C | C5: 인공지능 교과 탐구 | D5: 예술진체 | E5: 문학 | F5: 영어Ⅰ | G5: 세계시민과 지리 | H5: 대수 | I5: 예술진체 | J5: 세계사 | K5: 화학
B6: D | C6: 영어Ⅰ | D6: 생활과 인성Ⅰ | E6: 미적분Ⅰ | F6: 질문 기반 주제 탐구 | G6: 인공지능 기초 | H6: 물리학 | I6: 화학 | J6: 대수 | K6: 문학
B7: E | C7: 대수 | D7: 인공지능 교과 탐구 | E7: 영어Ⅰ | F7: 문학 | G7: 물리학 | H7: 예술진체 | I7: 사회와 문화 | J7: 생명과학 | K7: 지구과학
B8: F | C8: 미적분Ⅰ | D8: 영어Ⅰ | E8: 대수 | F8: 화학 | G8: 질문 기반 주제 탐구 | H8: 문학 | I8: 세계시민과 지리 | J8: 예술진체 | K8: 예술진체
B9: G | C9: 문학 | D9: 문학 | E9: 현대사회와 윤리 | F9: 사회와 문화 | G9: 예술진체 | H9: 영어Ⅰ | I9: 대수 | J9: 미적분Ⅰ | K9: 인공지능 교과 탐구
B10: H | C10: 예술진체 | D10: 대수 | E10: 물리학 | F10: 대수 | G10: 영어Ⅰ | H10: 화학 | I10: 매체 의사소통 | J10: 문학 | K10: 미적분Ⅰ
B16: 3학년 선택 | C16: 1반 | D16: 2반 | E16: 3반 | F16: 4반 | G16: 5반 | H16: 6반 | I16: 7반 | J16: 8반 | K16: 9반 | L16: 모둠학습
B17: A | C17: 언어와 매체 | D17: 수학과제 탐구 | E17: 수학과제 탐구 | F17: 심화 영어 독해Ⅰ | G17: 경제 수학 | H17: 확률과 통계 | I17: 심화 수학Ⅰ | J17: 심화 영어Ⅰ | K17: 확률과 통계
B18: B | C18: 현대문학 감상 | D18: 언어와 매체 | E18: 화법과 작문 | F18: 심화 영어Ⅰ | G18: 심화 영어 독해Ⅰ | H18: 언어와 매체 | I18: 인공지능 수학 | J18: 확률과 통계 | K18: 심화 수학Ⅰ
B19: C | C19: 심화 영어Ⅰ | D19: 화법과 작문 | E19: 언어와 매체 | F19: 확률과 통계 | G19: 심화 영어Ⅰ | H19: 경제 수학 | I19: 확률과 통계 | J19: 수학과제 탐구 | K19: 인공지능 수학
B20: D | C20: 화법과 작문 | D20: 현대문학 감상 | E20: 확률과 통계 | F20: 언어와 매체 | G20: 언어와 매체 | H20: 심화 영어 독해Ⅰ | I20: 수학과제 탐구 | J20: 심화 수학Ⅰ | K20: 심화 영어Ⅰ | L20: 수학과제 탐구
B21: E | C21: 생활과 윤리 | D21: 사회문제 탐구 | E21: 현대 세계의 변화 | F21: 화학Ⅱ | G21: 화학Ⅱ | H21: 생명과학Ⅱ | I21: 지구과학Ⅱ | J21: 융합과학 | K21: 데이터 과학과 머신러닝
B22: F | C22: 비교문화 | D22: 생활과 윤리 | E22: 사회문제 탐구 | F22: 생명과학Ⅱ | G22: 융합과학 | H22: 지구과학Ⅱ | I22: 융합과학 | J22: 데이터 과학과 머신러닝 | K22: 물리학Ⅱ
B23: G | C23: 사회문제 탐구 | D23: 여행지리 | E23: 생활과 윤리 | F23: 융합과학 | G23: 지구과학Ⅱ | H23: 화학Ⅱ | I23: 물리학Ⅱ | J23: 화학Ⅱ | K23: 융합과학 | L23: 현대 세계의 변화

Sheet Sheet2
A2: 101
A3: 102
A4: 103
A5: 104
A6: 105
A7: 106
A8: 107
A9: 108
A10: 109
A12: 201 | B12: <강의실 안내>
A13: 202 | B13: <강의실 안내>
A14: 203 | B14: <강의실 안내>
A15: 204 | B15: <강의실 안내>
A16: 205 | B16: <강의실 안내>
A17: 206 | B17: <강의실 안내>
A18: 207 | B18: <강의실 안내>
A19: 208 | B19: <강의실 안내>
A20: 209 | B20: <강의실 안내>
A22: 301 | B22: <강의실 안내>
A23: 302 | B23: <강의실 안내>
A24: 303 | B24: <강의실 안내>
... A30: 309 | B30: <강의실 안내>
